{"report": {"environment": {"Python": "3.6.6", "Platform": "Linux-4.15.0-38-generic-x86_64-with-Ubuntu-18.04-bionic"}, "tests": [{"name": "result.py::TestExample::test_example_1", "duration": 0.007088184356689453, "run_index": 0, "setup": {"name": "setup", "duration": 0.0031723976135253906, "outcome": "passed"}, "call": {"name": "call", "duration": 0.00043964385986328125, "outcome": "passed"}, "teardown": {"name": "teardown", "duration": 0.0003037452697753906, "outcome": "passed"}, "outcome": "passed"}, {"name": "result.py::TestExample::test_example_2", "duration": 0.0018241405487060547, "run_index": 1, "setup": {"name": "setup", "duration": 0.0005710124969482422, "outcome": "passed"}, "call": {"name": "call", "duration": 0.0003597736358642578, "outcome": "failed", "longrepr": "self = <result.TestExample testMethod=test_example_2>\n\n    def test_example_2(self):\n>       self.assertTrue(False, 'example of failed test')\nE       AssertionError: False is not true : example of failed test\n\nresult.py:8: AssertionError"}, "teardown": {"name": "teardown", "duration": 0.0003223419189453125, "outcome": "passed"}, "outcome": "failed"}, {"name": "result.py::TestExample::test_example_3", "duration": 0.0015332698822021484, "run_index": 2, "setup": {"name": "setup", "duration": 0.00041866302490234375, "outcome": "passed"}, "call": {"name": "call", "duration": 0.0003535747528076172, "outcome": "skipped", "longrepr": "('result.py', 9, 'Skipped: example of skipped test')"}, "teardown": {"name": "teardown", "duration": 0.00034236907958984375, "outcome": "passed"}, "outcome": "skipped"}], "summary": {"passed": 1, "failed": 1, "skipped": 1, "num_tests": 3, "duration": 0.07004213333129883}, "created_at": "2019-11-17 15:17:15.834569"}}